<?xml version="1.0"?>
<robot name="diffbot">

<link name="base_link">

  <visual>
    <geometry>
      <box size="0.5 0.4 0.2"/>
    </geometry>
  </visual>

  <collision>
    <geometry>
      <box size="0.5 0.4 0.2"/>
    </geometry>
  </collision>

  <inertial>
    <mass value="5"/>
    <origin xyz="0 0 0"/>
    <inertia ixx="0.2" ixy="0" ixz="0"
             iyy="0.2" iyz="0"
             izz="0.2"/>
  </inertial>

</link>


<link name="left_wheel">
  <visual>
    <geometry>
      <cylinder radius="0.1" length="0.05"/>
    </geometry>
  </visual>

  <collision>
    <geometry>
      <cylinder radius="0.1" length="0.05"/>
    </geometry>
  </collision>

  <inertial>
    <mass value="1"/>
    <origin xyz="0 0 0"/>
    <inertia
      ixx="0.01" ixy="0" ixz="0"
      iyy="0.01" iyz="0"
      izz="0.01"/>
  </inertial>

</link>


<link name="right_wheel">
  <visual>
    <geometry>
      <cylinder radius="0.1" length="0.05"/>
    </geometry>
  </visual>

  <collision>
    <geometry>
      <cylinder radius="0.1" length="0.05"/>
    </geometry>
  </collision>

  <inertial>
    <mass value="1"/>
    <origin xyz="0 0 0"/>
    <inertia
      ixx="0.01" ixy="0" ixz="0"
      iyy="0.01" iyz="0"
      izz="0.01"/>
  </inertial>

</link>


<joint name="left_wheel_joint" type="continuous">
  <parent link="base_link"/>
  <child link="left_wheel"/>
  <origin xyz="0 0.25 0"/>
  <axis xyz="0 1 0"/>
</joint>


<joint name="right_wheel_joint" type="continuous">
  <parent link="base_link"/>
  <child link="right_wheel"/>
  <origin xyz="0 -0.25 0"/>
  <axis xyz="0 1 0"/>
</joint>


<!-- ROS2 CONTROL -->

<ros2_control name="GazeboSystem" type="system">
  <hardware>
    <plugin>gz_ros2_control/GazeboSimSystem</plugin>
  </hardware>

  <joint name="left_wheel_joint">
    <command_interface name="velocity"/>
    <state_interface name="velocity"/>
    <state_interface name="position"/>
  </joint>

  <joint name="right_wheel_joint">
    <command_interface name="velocity"/>
    <state_interface name="velocity"/>
    <state_interface name="position"/>
  </joint>

</ros2_control>


<gazebo>
  
  <plugin filename="libgz_ros2_control-system.so"
          name="gz_ros2_control::GazeboSimROS2ControlPlugin">

    <parameters>$(find robot_sim)/config/controllers.yaml</parameters>

  </plugin>

</gazebo>

</robot>
